<?xml version="1.0"?>
<robot xmlns:xacro="http://wiki.ros.org/xacro">

  <xacro:macro name="create_wheel_link"
    params="
        link_name
        mesh_name
        xyz_offset
        *origin *mass *inertia">
    <link name="${link_name}">
      <visual>
        <origin xyz="0 0 0" rpy="0 0 0" />
        <geometry>
          <mesh filename="${mesh_dir}/${mesh_name}.DAE" />
        </geometry>
      </visual>
      <collision>
        <origin xyz="${xyz_offset}" rpy="${M_PI/2} 0 0" />
        <geometry>
          <cylinder radius="0.035" length="0.009" />
        </geometry>
      </collision>
      <inertial>
        <xacro:insert_block name="origin" />
        <xacro:insert_block name="mass" />
        <xacro:insert_block name="inertia" />
      </inertial>
    </link>
  </xacro:macro>

  <xacro:macro name="create_wheel_joint"
    params="
        joint_name
        link_name
        xyz_offset">
    <joint name="${joint_name}" type="continuous">
      <parent link="$(arg prefix)base_link" />
      <child link="${link_name}" />
      <origin rpy="0 0 0" xyz="${xyz_offset}" />
      <axis xyz="0 1 0" />
      <limit effort="3.9" velocity="36.92" />
    </joint>
  </xacro:macro>

  <xacro:create_wheel_link
    link_name="$(arg prefix)right_front_wheel_link"
    mesh_name="right_front_wheel_link"
    xyz_offset="0 -0.021 0">
    <origin xyz="6.832E-08 -0.0098111 -7.0676E-07" rpy="0 0 0" />
    <mass value="${wheel_mass}" />
    <inertia
      ixx="1.996E-05"
      ixy="-1.4777E-14"
      ixz="6.8928E-11"
      iyy="3.4111E-05"
      iyz="-1.8473E-15"
      izz="1.996E-05" />
  </xacro:create_wheel_link>

  <xacro:create_wheel_link
    link_name="$(arg prefix)left_front_wheel_link"
    mesh_name="left_front_wheel_link"
    xyz_offset="0 0.021 0">
    <origin xyz="-6.8329E-08 0.0098111 -7.0684E-07" rpy="0 0 0" />
    <mass value="${wheel_mass}" />
    <inertia
      ixx="1.996E-05"
      ixy="-1.4777E-14"
      ixz="6.8928E-11"
      iyy="3.4111E-05"
      iyz="-1.8473E-15"
      izz="1.996E-05" />
  </xacro:create_wheel_link>

  <xacro:create_wheel_link
    link_name="$(arg prefix)right_rear_wheel_link"
    mesh_name="right_rear_wheel_link"
    xyz_offset="0 -0.021 0">
    <origin xyz="6.832E-08 -0.0098111 -7.0676E-07" rpy="0 0 0" />
    <mass value="${wheel_mass}" />
    <inertia
      ixx="1.996E-05"
      ixy="-1.4777E-14"
      ixz="-6.8928E-11"
      iyy="3.4111E-05"
      iyz="1.8473E-15"
      izz="1.996E-05" />
  </xacro:create_wheel_link>

  <xacro:create_wheel_link
    link_name="$(arg prefix)left_rear_wheel_link"
    mesh_name="left_rear_wheel_link"
    xyz_offset="0 0.021 0">
    <origin xyz="-6.8366E-08 0.0098111 -7.068E-07" rpy="0 0 0" />
    <mass value="${wheel_mass}" />
    <inertia
      ixx="1.996E-05"
      ixy="-1.4777E-14"
      ixz="-6.8928E-11"
      iyy="3.4111E-05"
      iyz="1.8473E-15"
      izz="1.996E-05" />
  </xacro:create_wheel_link>

  <xacro:create_wheel_joint
    joint_name="$(arg prefix)right_front_wheel_joint"
    link_name="$(arg prefix)right_front_wheel_link"
    xyz_offset="0.0725 -0.08661 -0.026385"
  />
  <xacro:create_wheel_joint
    joint_name="$(arg prefix)left_front_wheel_joint"
    link_name="$(arg prefix)left_front_wheel_link"
    xyz_offset="0.0725 0.08939 -0.026385"
  />
  <xacro:create_wheel_joint
    joint_name="$(arg prefix)right_rear_wheel_joint"
    link_name="$(arg prefix)right_rear_wheel_link"
    xyz_offset="-0.1005 -0.08661 -0.026385"
  />
  <xacro:create_wheel_joint
    joint_name="$(arg prefix)left_rear_wheel_joint"
    link_name="$(arg prefix)left_rear_wheel_link"
    xyz_offset="-0.1005 0.08939 -0.026385"
  />
</robot>